Workbook
Name Dia_Firma: #REF!

Sheet Cálculo pagos
B2: Préstamo | C2: 100000
B3: Interés ordinario | C3: 0.12
B4: Intereses anuales | C4: =C2*C3 -> 12000
B5: Intereses mensuales (habitual) | C5: =C4/12 -> 1000
B7: Participación | C7: 20000
B8: % participación | C8: =C7/C2 -> 0.2
B9: Factor de este mes | C9: 1 | D9: Este factor responde a la cantidad de días que hay que pagar (puede ser distinto de 1 en los 2 primeros pagos)
B10: Devengado mensual habitual | C10: =C5*C8*C9 -> 200
B11: % gestión | C11: 0.02
B12: Gestión | C12: =C7*C11/12*C9 -> 33.333333
B13: Bruto | C13: =C10-C12 -> 166.66667
B14: % IRPF | C14: 0.19
B15: IRPF | C15: =C13*19% -> 31.666667
B16: Neto | C16: =C13-C15 -> 135
B18: Rentabilidad anualizada partícipe | C18: =C13*12/C7 -> 0.1

Sheet Dashboard
F1: Activo | G1: Judicializado
B2: En curso | C2: =F2+G2 -> 2781010 | F2: =SUMIFS(T_Prestamos[Importe],T_Prestamos[Situación],"Activos") -> 2690710 | G2: =SUMIFS(T_Prestamos[Importe],T_Prestamos[Situación],"Judicializados") -> 90300
B3: Activo | C3: =F3+G3 -> 2656056.3 | F3: =SUMIFS(T_Prestamos[Pendiente],T_Prestamos[Situación],"Activos") -> 2597747.2 | G3: =SUMIFS(T_Prestamos[Pendiente],T_Prestamos[Situación],"Judicializados") -> 58309.061 | K3: Desplegadas
B4: Participado | C4: =F4+G4 -> 1475000 | D4: =F4/C3 -> 0.55533462 | F4: 1475000 | K4: En Curso
B5: Promocima (Activo) | C5: =F5+G5 -> 1181056.3 | D5: =C5/C3 -> 0.44466538 | F5: =F3-F4 -> 1122747.2 | G5: =G3-G4 -> 58309.061 | K5: Activas
A6: 2026 | B6: Intereses | F6: =SUMIFS(T_Prestamos[Int. Anual],T_Prestamos[Situación],"Activos") -> 289988.83 | K6: Al día
B7: Rentabilidad media | F7: =F6/F3 -> 0.11163089 | K7: Con retraso
B8: Intereses partícipes | F8: =SUM(T_Participaciones[Intereses]) -> 165758.75 | K8: Judicializadas
B9: Rent. Partícipes | F9: =F8/F4 -> 0.11237881 | K9: Canceladas
B10: Ingresos gestión | F10: =SUMIFS(T_Participaciones[Gestión],T_Participaciones[Situación],"Activa") -> 28500
B11: Ingresos Promocima | F11: =F6-F8+F10 -> 152730.08
B12: Rent. Promocima | F12: =F11/F5 -> 0.13603247
B13: Apertura LTM | F13: =SUM(T_Prestamos[Aperturas LTM]) -> 25612.225
B14: Papertura LTM Participada | F14: =SUM(T_Participaciones[Apertura LTM]) -> 1000
B16: KPI 1 | E16: KPI 2 | H16: KPI 3 | K16: KPI 4 | N16: KPI 5
B17: En cruso | C17: =C2 -> 2781010 | E17: Ingresos Anuales op. Activas | F17: =F6 -> 289988.83 | H17: Operaciones Totales | I17: =COUNT(T_Prestamos[Centro coste]) -> 65 | K17: Total Garantías op en curso | L17: =SUMIFS(T_Prestamos[Garantía],T_Prestamos[Situación],"Activos")+SUMIFS(T_Prestamos[Garantía],T_Prestamos[Situación],"Judicializados") -> 10924830 | N17: Duración media op en curso | O17: =(SUMIFS(T_Prestamos[Duración],T_Prestamos[Situación],"Activos")+SUMIFS(T_Prestamos[Duración],T_Prestamos[Situación],"Judicializados"))/(COUNTIFS(T_Prestamos[Situación],"Activos")+COUNTIFS(T_Prestamos[Situación],"Judicializados")) -> 1342.7692
B18: Activo | C18: =F3 -> 2597747.2 | E18: Ingresos Anuales part. Activas | F18: =F8 -> 165758.75 | H18: Operaciones Canceladas | I18: =COUNTIFS(T_Prestamos[Situación],"Cancelados") -> 39 | K18: LTV op vivas | L18: =C2/L17 -> 0.25455866 | N18: Duración media op canceladas | O18: =SUMIFS(T_Prestamos[Duración],T_Prestamos[Situación],"Cancelados")/COUNTIFS(T_Prestamos[Situación],"Cancelados") -> 721.25641
B19: Judicializado | C19: =G3 -> 58309.061 | E19: Ingresos Promocima Gestión | F19: =F10 -> 28500 | H19: Operaciones En curso | I19: =I17-I18 -> 26 | K19: Total garantías partícipes | L19: =SUM(T_Participaciones[Garantía]) -> 6091055.9 | N19: Duración media op activas | O19: =SUMIFS(T_Prestamos[Duración],T_Prestamos[Situación],"Activos")/COUNTIFS(T_Prestamos[Situación],"Activos") -> 1120.0455
B20: % judicializado | C20: =C19/C17 -> 0.020966865 | E20: Ingresos Apert. Promocima (Últimos 12 meses) | F20: =F13-F14 -> 24612.225 | H20: Operaciones Judicializadas | I20: =COUNTIFS(T_Prestamos[Situación],"Judicializados") -> 4 | K20: LTV op participadas | L20: =F4/L19 -> 0.24215834 | N20: Duración media op judicializadas | O20: =SUMIFS(T_Prestamos[Duración],T_Prestamos[Situación],"Judicializados")/COUNTIFS(T_Prestamos[Situación],"Judicializados") -> 2567.75
B21: Participado Activo | C21: =F4 -> 1475000 | E21: Rentabilidad Activas | F21: =F17/C18 -> 0.11163089 | H21: Operaciones Activas | I21: =COUNTIFS(T_Prestamos[Situación],"Activos") -> 22
B22: Participado Judicializado | C22: =G4 -> 0 | E22: Rentabilidad Partícipes | F22: =F8/F4 -> 0.11237881 | H22: Operaciones Al día
B23: % Judic. Partícipes | C23: =C22/C21 -> 0 | E23: Rentabilidad Total Promocima | F23: =(F17-F18+F19+F20)/F5 -> 0.1579539 | H23: Operaciones Con retraso
E26: En curso | F26: 2672058
E27: Activas | F27: 2598162
E28: Rentabilidad | F28: 289444
E29: Gestión | F29: 28500
E30: Apertura | F30: 25612
E31: Rent op activas | F31: =F28/F27 -> 0.11140337
E32: OJO, el calcula esto | F32: =F28/F26 -> 0.1083225
E34: Participadas | F34: 1475000
E35: Rentabil. Partícipes | F35: 165759
E36: Rent. Part. | F36: =F35/F34 -> 0.11237898
E37: Rent tot. Promocima | F37: =(F28-F35+F29+F30)/(F27-F34) -> 0.15830041
E39: Garantías | F39: 10003131
E40: LTV op.activas | F40: =F26/F39 -> 0.26712216
E41: Garantías participadas | F41: 5371230
E42: LTV op.activas | F42: =F34/F41 -> 0.27461122

Sheet Tabla Préstamos
B2: =COLUMN()-1 -> 1 | C2: =COLUMN()-1 -> 2 | D2: =COLUMN()-1 -> 3 | E2: =COLUMN()-1 -> 4 | F2: =COLUMN()-1 -> 5 | G2: =COLUMN()-1 -> 6 | H2: =COLUMN()-1 -> 7 | I2: =COLUMN()-1 -> 8 | ... O2: =COLUMN()-1 -> 14 | Q2: =COLUMN()-1 -> 16 | R2: =COLUMN()-1 -> 17 | S2: =COLUMN()-1 -> 18 | T2: =COLUMN()-1 -> 19 | U2: =COLUMN()-1 -> 20 | V2: =COLUMN()-1 -> 21 | W2: =COLUMN()-1 -> 22 | X2: =COLUMN()-1 -> 23 | Z2: =COLUMN()-1 -> 25 | AA2: =COLUMN()-1 -> 26
B3: Créditos activos
B4: Centro coste | C4: Nombre | D4: firma préstamo | E4: Años | F4: Importe | G4: % interés ordinario | H4: % interés demora | I4: Garantía | J4: LTV vs Pendiente | K4: Destinatario | L4: Tipo préstamo | M4: Intermediario | N4: Situación | O4: Fecha cancelación | P4: Importe retraso | Q4: Duración | R4: Meses | S4: Pendiente | T4: Intereses anuales | U4: % apertura | V4: Apertura | W4: Observaciones | X4: Prestatario | Y4: Primera cuota año | Z4: Int. Anual | AA4: Aperturas LTM
B5: 2001 | C5: Préstamo Peinado Vives | D5: 42883 | E5: 10 | F5: 28500 | G5: 0.12 | H5: 0.12 | J5: =IF(T_Prestamos[[#This Row],[Garantía]]="","",T_Prestamos[[#This Row],[Pendiente]]/T_Prestamos[[#This Row],[Garantía]]) | K5: Física | L5: Francés | M5: Silex | N5: Cancelados | O5: 45770 | Q5: =IF(T_Prestamos[[#This Row],[Situación]]="Cancelados",T_Prestamos[[#This Row],[Fecha cancelación]],TODAY())-T_Prestamos[[#This Row],[firma préstamo]] -> 2887 | R5: =IF(T_Prestamos[[#This Row],[Situación]]="Cancelada","",DATEDIF(T_Prestamos[[#This Row],[firma préstamo]],TODAY(),"m")) -> 105 | S5: =IF(T_Prestamos[[#This Row],[Situación]]="Cancelados",0,IF(T_Prestamos[[#This Row],[Tipo préstamo]]="Americano",T_Prestamos[[#This Row],[Importe]],T_Prestamos[[#This Row],[Importe]]+CUMPRINC(G5/12,E5*12,F5,1,R5,0))) -> 0 | T5: =IF(T_Prestamos[[#This Row],[Situación]]="Cancelados",0,IF(T_Prestamos[[#This Row],[Tipo préstamo]]="Americano",T_Prestamos[[#This Row],[Pendiente]]*T_Prestamos[[#This Row],[% interés ordinario]],-CUMIPMT(G5/12,E5*12,F5,R5,R5+11,0))) -> 0 | U5: 0 | V5: =T_Prestamos[[#This Row],[% apertura]]*T_Prestamos[[#This Row],[Importe]] -> 0 | Y5: =IF(T_Prestamos[[#This Row],[Situación]]="Activos",IF(T_Prestamos[[#This Row],[Tipo préstamo]]="Francés",DATEDIF(T_Prestamos[[#This Row],[firma préstamo]],DATE(YEAR(TODAY()),1,1),"m"),0),0) -> 0 | Z5: =IF(T_Prestamos[[#This Row],[Situación]]="Activos",IF(T_Prestamos[[#This Row],[Tipo préstamo]]="Americano",T_Prestamos[[#This Row],[Importe]]*T_Prestamos[[#This Row],[% interés ordinario]],-CUMIPMT(T_Prestamos[[#This Row],[% interés ordinario]]/12,T_Prestamos[[#This Row],[Años]]*12,T_Prestamos[[#This Row],[Importe]],T_Prestamos[[#This Row],[Primera cuota año]],T_Prestamos[[#This Row],[Primera cuota año]]+11,0)),0) -> 0 | AA5: =IF(T_Prestamos[[#This Row],[firma préstamo]]>DATE(YEAR(TODAY())-1,MONTH(TODAY()),DAY(TODAY())),T_Prestamos[[#This Row],[Importe]]*T_Prestamos[[#This Row],[% apertura]],0) -> 0
B6: 2002 | C6: Présamo Panadero Hinarejos | D6: 43003 | E6: 11 | F6: 47500 | G6: 0.125 | H6: 0.145 | J6: =IF(T_Prestamos[[#This Row],[Garantía]]="","",T_Prestamos[[#This Row],[Pendiente]]/T_Prestamos[[#This Row],[Garantía]]) | K6: Física | L6: Francés | M6: Silex | N6: Cancelados | O6: 43532 | Q6: =IF(T_Prestamos[[#This Row],[Situación]]="Cancelados",T_Prestamos[[#This Row],[Fecha cancelación]],TODAY())-T_Prestamos[[#This Row],[firma préstamo]] -> 529 | R6: =IF(T_Prestamos[[#This Row],[Situación]]="Cancelada","",DATEDIF(T_Prestamos[[#This Row],[firma préstamo]],TODAY(),"m")) -> 101 | S6: =IF(T_Prestamos[[#This Row],[Situación]]="Cancelados",0,IF(T_Prestamos[[#This Row],[Tipo préstamo]]="Americano",T_Prestamos[[#This Row],[Importe]],T_Prestamos[[#This Row],[Importe]]+CUMPRINC(G6/12,E6*12,F6,1,R6,0))) -> 0 | T6: =IF(T_Prestamos[[#This Row],[Situación]]="Cancelados",0,IF(T_Prestamos[[#This Row],[Tipo préstamo]]="Americano",T_Prestamos[[#This Row],[Pendiente]]*T_Prestamos[[#This Row],[% interés ordinario]],-CUMIPMT(G6/12,E6*12,F6,R6,R6+11,0))) -> 0 | U6: 0 | V6: =T_Prestamos[[#This Row],[% apertura]]*T_Prestamos[[#This Row],[Importe]] -> 0 | Y6: =IF(T_Prestamos[[#This Row],[Situación]]="Activos",IF(T_Prestamos[[#This Row],[Tipo préstamo]]="Francés",DATEDIF(T_Prestamos[[#This Row],[firma préstamo]],DATE(YEAR(TODAY()),1,1),"m"),0),0) -> 0 | Z6: =IF(T_Prestamos[[#This Row],[Situación]]="Activos",IF(T_Prestamos[[#This Row],[Tipo préstamo]]="Americano",T_Prestamos[[#This Row],[Importe]]*T_Prestamos[[#This Row],[% interés ordinario]],-CUMIPMT(T_Prestamos[[#This Row],[% interés ordinario]]/12,T_Prestamos[[#This Row],[Años]]*12,T_Prestamos[[#This Row],[Importe]],T_Prestamos[[#This Row],[Primera cuota año]],T_Prestamos[[#This Row],[Primera cuota año]]+11,0)),0) -> 0 | AA6: =IF(T_Prestamos[[#This Row],[firma préstamo]]>DATE(YEAR(TODAY())-1,MONTH(TODAY()),DAY(TODAY())),T_Prestamos[[#This Row],[Importe]]*T_Prestamos[[#This Row],[% apertura]],0) -> 0
B7: 2003 | C7: Préstamo Carlos Santiago Reyes | D7: 43041 | E7: 10 | F7: 45000 | G7: 0.125 | H7: =T_Prestamos[[#This Row],[% interés ordinario]]+3% -> 0.155 | J7: =IF(T_Prestamos[[#This Row],[Garantía]]="","",T_Prestamos[[#This Row],[Pendiente]]/T_Prestamos[[#This Row],[Garantía]]) | K7: Física | L7: Francés | M7: Silex | N7: Cancelados | O7: 44542 | Q7: =IF(T_Prestamos[[#This Row],[Situación]]="Cancelados",T_Prestamos[[#This Row],[Fecha cancelación]],TODAY())-T_Prestamos[[#This Row],[firma préstamo]] -> 1501 | R7: =IF(T_Prestamos[[#This Row],[Situación]]="Cancelada","",DATEDIF(T_Prestamos[[#This Row],[firma préstamo]],TODAY(),"m")) -> 100 | S7: =IF(T_Prestamos[[#This Row],[Situación]]="Cancelados",0,IF(T_Prestamos[[#This Row],[Tipo préstamo]]="Americano",T_Prestamos[[#This Row],[Importe]],T_Prestamos[[#This Row],[Importe]]+CUMPRINC(G7/12,E7*12,F7,1,R7,0))) -> 0 | T7: =IF(T_Prestamos[[#This Row],[Situación]]="Cancelados",0,IF(T_Prestamos[[#This Row],[Tipo préstamo]]="Americano",T_Prestamos[[#This Row],[Pendiente]]*T_Prestamos[[#This Row],[% interés ordinario]],-CUMIPMT(G7/12,E7*12,F7,R7,R7+11,0))) -> 0 | U7: 0 | V7: =T_Prestamos[[#This Row],[% apertura]]*T_Prestamos[[#This Row],[Importe]] -> 0 | Y7: =IF(T_Prestamos[[#This Row],[Situación]]="Activos",IF(T_Prestamos[[#This Row],[Tipo préstamo]]="Francés",DATEDIF(T_Prestamos[[#This Row],[firma préstamo]],DATE(YEAR(TODAY()),1,1),"m"),0),0) -> 0 | Z7: =IF(T_Prestamos[[#This Row],[Situación]]="Activos",IF(T_Prestamos[[#This Row],[Tipo préstamo]]="Americano",T_Prestamos[[#This Row],[Importe]]*T_Prestamos[[#This Row],[% interés ordinario]],-CUMIPMT(T_Prestamos[[#This Row],[% interés ordinario]]/12,T_Prestamos[[#This Row],[Años]]*12,T_Prestamos[[#This Row],[Importe]],T_Prestamos[[#This Row],[Primera cuota año]],T_Prestamos[[#This Row],[Primera cuota año]]+11,0)),0) -> 0 | AA7: =IF(T_Prestamos[[#This Row],[firma préstamo]]>DATE(YEAR(TODAY())-1,MONTH(TODAY()),DAY(TODAY())),T_Prestamos[[#This Row],[Importe]]*T_Prestamos[[#This Row],[% apertura]],0) -> 0
B8: 2004 | C8: Las Palmas de GC - Persona física | D8: 43040 | E8: 10 | F8: 24000 | G8: 0.15 | H8: 0.17 | I8: 91577 | J8: =IF(T_Prestamos[[#This Row],[Garantía]]="","",T_Prestamos[[#This Row],[Pendiente]]/T_Prestamos[[#This Row],[Garantía]]) -> 0.074413049 | K8: Física | L8: Francés | M8: Silex | N8: Activos | Q8: =IF(T_Prestamos[[#This Row],[Situación]]="Cancelados",T_Prestamos[[#This Row],[Fecha cancelación]],TODAY())-T_Prestamos[[#This Row],[firma préstamo]] -> 3056 | R8: =IF(T_Prestamos[[#This Row],[Situación]]="Cancelada","",DATEDIF(T_Prestamos[[#This Row],[firma préstamo]],TODAY(),"m")) -> 100 | S8: =IF(T_Prestamos[[#This Row],[Situación]]="Cancelados",0,IF(T_Prestamos[[#This Row],[Tipo préstamo]]="Americano",T_Prestamos[[#This Row],[Importe]],T_Prestamos[[#This Row],[Importe]]+CUMPRINC(G8/12,E8*12,F8,1,R8,0))) -> 6814.5238 | T8: =IF(T_Prestamos[[#This Row],[Situación]]="Cancelados",0,IF(T_Prestamos[[#This Row],[Tipo préstamo]]="Americano",T_Prestamos[[#This Row],[Pendiente]]*T_Prestamos[[#This Row],[% interés ordinario]],-CUMIPMT(G8/12,E8*12,F8,R8,R8+11,0))) -> 810.28225 | U8: 0 | V8: =T_Prestamos[[#This Row],[% apertura]]*T_Prestamos[[#This Row],[Importe]] -> 0 | X8: Domingo Juan Santana Araya | Y8: =IF(T_Prestamos[[#This Row],[Situación]]="Activos",IF(T_Prestamos[[#This Row],[Tipo préstamo]]="Francés",DATEDIF(T_Prestamos[[#This Row],[firma préstamo]],DATE(YEAR(TODAY()),1,1),"m"),0),0) -> 98 | Z8: =IF(T_Prestamos[[#This Row],[Situación]]="Activos",IF(T_Prestamos[[#This Row],[Tipo préstamo]]="Americano",T_Prestamos[[#This Row],[Importe]]*T_Prestamos[[#This Row],[% interés ordinario]],-CUMIPMT(T_Prestamos[[#This Row],[% interés ordinario]]/12,T_Prestamos[[#This Row],[Años]]*12,T_Prestamos[[#This Row],[Importe]],T_Prestamos[[#This Row],[Primera cuota año]],T_Prestamos[[#This Row],[Primera cuota año]]+11,0)),0) -> 904.41767 | AA8: =IF(T_Prestamos[[#This Row],[firma préstamo]]>DATE(YEAR(TODAY())-1,MONTH(TODAY()),DAY(TODAY())),T_Prestamos[[#This Row],[Importe]]*T_Prestamos[[#This Row],[% apertura]],0) -> 0
B9: 2005 | C9: Préstamo Juan Melchor Torrens Pou | D9: 43054 | E9: 1 | F9: 14500 | G9: 0.15 | H9: 0.17 | J9: =IF(T_Prestamos[[#This Row],[Garantía]]="","",T_Prestamos[[#This Row],[Pendiente]]/T_Prestamos[[#This Row],[Garantía]]) | K9: Física | L9: Francés | M9: Silex | N9: Cancelados | O9: 43496 | Q9: =IF(T_Prestamos[[#This Row],[Situación]]="Cancelados",T_Prestamos[[#This Row],[Fecha cancelación]],TODAY())-T_Prestamos[[#This Row],[firma préstamo]] -> 442 | R9: =IF(T_Prestamos[[#This Row],[Situación]]="Cancelada","",DATEDIF(T_Prestamos[[#This Row],[firma préstamo]],TODAY(),"m")) -> 100 | S9: =IF(T_Prestamos[[#This Row],[Situación]]="Cancelados",0,IF(T_Prestamos[[#This Row],[Tipo préstamo]]="Americano",T_Prestamos[[#This Row],[Importe]],T_Prestamos[[#This Row],[Importe]]+CUMPRINC(G9/12,E9*12,F9,1,R9,0))) -> 0 | T9: =IF(T_Prestamos[[#This Row],[Situación]]="Cancelados",0,IF(T_Prestamos[[#This Row],[Tipo préstamo]]="Americano",T_Prestamos[[#This Row],[Pendiente]]*T_Prestamos[[#This Row],[% interés ordinario]],-CUMIPMT(G9/12,E9*12,F9,R9,R9+11,0))) -> 0 | U9: 0 | V9: =T_Prestamos[[#This Row],[% apertura]]*T_Prestamos[[#This Row],[Importe]] -> 0 | Y9: =IF(T_Prestamos[[#This Row],[Situación]]="Activos",IF(T_Prestamos[[#This Row],[Tipo préstamo]]="Francés",DATEDIF(T_Prestamos[[#This Row],[firma préstamo]],DATE(YEAR(TODAY()),1,1),"m"),0),0) -> 0 | Z9: =IF(T_Prestamos[[#This Row],[Situación]]="Activos",IF(T_Prestamos[[#This Row],[Tipo préstamo]]="Americano",T_Prestamos[[#This Row],[Importe]]*T_Prestamos[[#This Row],[% interés ordinario]],-CUMIPMT(T_Prestamos[[#This Row],[% interés ordinario]]/12,T_Prestamos[[#This Row],[Años]]*12,T_Prestamos[[#This Row],[Importe]],T_Prestamos[[#This Row],[Primera cuota año]],T_Prestamos[[#This Row],[Primera cuota año]]+11,0)),0) -> 0 | AA9: =IF(T_Prestamos[[#This Row],[firma préstamo]]>DATE(YEAR(TODAY())-1,MONTH(TODAY()),DAY(TODAY())),T_Prestamos[[#This Row],[Importe]]*T_Prestamos[[#This Row],[% apertura]],0) -> 0
B10: 2006 | C10: Préstamo Juliana Joval Esque | D10: 43055 | E10: 10 | F10: 13000 | G10: 0.15 | H10: 0.17 | J10: =IF(T_Prestamos[[#This Row],[Garantía]]="","",T_Prestamos[[#This Row],[Pendiente]]/T_Prestamos[[#This Row],[Garantía]]) | K10: Física | L10: Francés | M10: Silex | N10: Cancelados | O10: 45188 | Q10: =IF(T_Prestamos[[#This Row],[Situación]]="Cancelados",T_Prestamos[[#This Row],[Fecha cancelación]],TODAY())-T_Prestamos[[#This Row],[firma préstamo]] -> 2133 | R10: =IF(T_Prestamos[[#This Row],[Situación]]="Cancelada","",DATEDIF(T_Prestamos[[#This Row],[firma préstamo]],TODAY(),"m")) -> 99 | S10: =IF(T_Prestamos[[#This Row],[Situación]]="Cancelados",0,IF(T_Prestamos[[#This Row],[Tipo préstamo]]="Americano",T_Prestamos[[#This Row],[Importe]],T_Prestamos[[#This Row],[Importe]]+CUMPRINC(G10/12,E10*12,F10,1,R10,0))) -> 0 | T10: =IF(T_Prestamos[[#This Row],[Situación]]="Cancelados",0,IF(T_Prestamos[[#This Row],[Tipo préstamo]]="Americano",T_Prestamos[[#This Row],[Pendiente]]*T_Prestamos[[#This Row],[% interés ordinario]],-CUMIPMT(G10/12,E10*12,F10,R10,R10+11,0))) -> 0 | U10: 0 | V10: =T_Prestamos[[#This Row],[% apertura]]*T_Prestamos[[#This Row],[Importe]] -> 0 | Y10: =IF(T_Prestamos[[#This Row],[Situación]]="Activos",IF(T_Prestamos[[#This Row],[Tipo préstamo]]="Francés",DATEDIF(T_Prestamos[[#This Row],[firma préstamo]],DATE(YEAR(TODAY()),1,1),"m"),0),0) -> 0 | Z10: =IF(T_Prestamos[[#This Row],[Situación]]="Activos",IF(T_Prestamos[[#This Row],[Tipo préstamo]]="Americano",T_Prestamos[[#This Row],[Importe]]*T_Prestamos[[#This Row],[% interés ordinario]],-CUMIPMT(T_Prestamos[[#This Row],[% interés ordinario]]/12,T_Prestamos[[#This Row],[Años]]*12,T_Prestamos[[#This Row],[Importe]],T_Prestamos[[#This Row],[Primera cuota año]],T_Prestamos[[#This Row],[Primera cuota año]]+11,0)),0) -> 0 | AA10: =IF(T_Prestamos[[#This Row],[firma préstamo]]>DATE(YEAR(TODAY())-1,MONTH(TODAY()),DAY(TODAY())),T_Prestamos[[#This Row],[Importe]]*T_Prestamos[[#This Row],[% apertura]],0) -> 0
B11: 2007 | C11: Préstamo Mª Isabel González Sáres | D11: 43055 | E11: 5 | F11: 16500 | G11: 0.15 | H11: 0.17 | J11: =IF(T_Prestamos[[#This Row],[Garantía]]="","",T_Prestamos[[#This Row],[Pendiente]]/T_Prestamos[[#This Row],[Garantía]]) | K11: Física | L11: Francés | M11: Silex | N11: Cancelados | O11: 43171 | Q11: =IF(T_Prestamos[[#This Row],[Situación]]="Cancelados",T_Prestamos[[#This Row],[Fecha cancelación]],TODAY())-T_Prestamos[[#This Row],[firma préstamo]] -> 116 | R11: =IF(T_Prestamos[[#This Row],[Situación]]="Cancelada","",DATEDIF(T_Prestamos[[#This Row],[firma préstamo]],TODAY(),"m")) -> 99 | S11: =IF(T_Prestamos[[#This Row],[Situación]]="Cancelados",0,IF(T_Prestamos[[#This Row],[Tipo préstamo]]="Americano",T_Prestamos[[#This Row],[Importe]],T_Prestamos[[#This Row],[Importe]]+CUMPRINC(G11/12,E11*12,F11,1,R11,0))) -> 0 | T11: =IF(T_Prestamos[[#This Row],[Situación]]="Cancelados",0,IF(T_Prestamos[[#This Row],[Tipo préstamo]]="Americano",T_Prestamos[[#This Row],[Pendiente]]*T_Prestamos[[#This Row],[% interés ordinario]],-CUMIPMT(G11/12,E11*12,F11,R11,R11+11,0))) -> 0 | U11: 0 | V11: =T_Prestamos[[#This Row],[% apertura]]*T_Prestamos[[#This Row],[Importe]] -> 0 | Y11: =IF(T_Prestamos[[#This Row],[Situación]]="Activos",IF(T_Prestamos[[#This Row],[Tipo préstamo]]="Francés",DATEDIF(T_Prestamos[[#This Row],[firma préstamo]],DATE(YEAR(TODAY()),1,1),"m"),0),0) -> 0 | Z11: =IF(T_Prestamos[[#This Row],[Situación]]="Activos",IF(T_Prestamos[[#This Row],[Tipo préstamo]]="Americano",T_Prestamos[[#This Row],[Importe]]*T_Prestamos[[#This Row],[% interés ordinario]],-CUMIPMT(T_Prestamos[[#This Row],[% interés ordinario]]/12,T_Prestamos[[#This Row],[Años]]*12,T_Prestamos[[#This Row],[Importe]],T_Prestamos[[#This Row],[Primera cuota año]],T_Prestamos[[#This Row],[Primera cuota año]]+11,0)),0) -> 0 | AA11: =IF(T_Prestamos[[#This Row],[firma préstamo]]>DATE(YEAR(TODAY())-1,MONTH(TODAY()),DAY(TODAY())),T_Prestamos[[#This Row],[Importe]]*T_Prestamos[[#This Row],[% apertura]],0) -> 0
B12: 2008 | C12: Préstamo Vidal Yagüe - Ibiza | D12: 42797 | E12: 10 | F12: 26500 | G12: 0.15 | H12: 0.17 | J12: =IF(T_Prestamos[[#This Row],[Garantía]]="","",T_Prestamos[[#This Row],[Pendiente]]/T_Prestamos[[#This Row],[Garantía]]) | K12: Física | L12: Francés | M12: Silex | N12: Cancelados | O12: 43090 | Q12: =IF(T_Prestamos[[#This Row],[Situación]]="Cancelados",T_Prestamos[[#This Row],[Fecha cancelación]],TODAY())-T_Prestamos[[#This Row],[firma préstamo]] -> 293 | R12: =IF(T_Prestamos[[#This Row],[Situación]]="Cancelada","",DATEDIF(T_Prestamos[[#This Row],[firma préstamo]],TODAY(),"m")) -> 108 | S12: =IF(T_Prestamos[[#This Row],[Situación]]="Cancelados",0,IF(T_Prestamos[[#This Row],[Tipo préstamo]]="Americano",T_Prestamos[[#This Row],[Importe]],T_Prestamos[[#This Row],[Importe]]+CUMPRINC(G12/12,E12*12,F12,1,R12,0))) -> 0 | T12: =IF(T_Prestamos[[#This Row],[Situación]]="Cancelados",0,IF(T_Prestamos[[#This Row],[Tipo préstamo]]="Americano",T_Prestamos[[#This Row],[Pendiente]]*T_Prestamos[[#This Row],[% interés ordinario]],-CUMIPMT(G12/12,E12*12,F12,R12,R12+11,0))) -> 0 | U12: 0 | V12: =T_Prestamos[[#This Row],[% apertura]]*T_Prestamos[[#This Row],[Importe]] -> 0 | Y12: =IF(T_Prestamos[[#This Row],[Situación]]="Activos",IF(T_Prestamos[[#This Row],[Tipo préstamo]]="Francés",DATEDIF(T_Prestamos[[#This Row],[firma préstamo]],DATE(YEAR(TODAY()),1,1),"m"),0),0) -> 0 | Z12: =IF(T_Prestamos[[#This Row],[Situación]]="Activos",IF(T_Prestamos[[#This Row],[Tipo préstamo]]="Americano",T_Prestamos[[#This Row],[Importe]]*T_Prestamos[[#This Row],[% interés ordinario]],-CUMIPMT(T_Prestamos[[#This Row],[% interés ordinario]]/12,T_Prestamos[[#This Row],[Años]]*12,T_Prestamos[[#This Row],[Importe]],T_Prestamos[[#This Row],[Primera cuota año]],T_Prestamos[[#This Row],[Primera cuota año]]+11,0)),0) -> 0 | AA12: =IF(T_Prestamos[[#This Row],[firma préstamo]]>DATE(YEAR(TODAY())-1,MONTH(TODAY()),DAY(TODAY())),T_Prestamos[[#This Row],[Importe]]*T_Prestamos[[#This Row],[% apertura]],0) -> 0
B13: 2009 | C13: Préstamos Jaume Boixadós | D13: 42648 | E13: 3 | F13: 16000 | G13: 0.125 | H13: 0.125 | J13: =IF(T_Prestamos[[#This Row],[Garantía]]="","",T_Prestamos[[#This Row],[Pendiente]]/T_Prestamos[[#This Row],[Garantía]]) | K13: Física | L13: Americano | M13: Silex | N13: Cancelados | O13: 43586 | Q13: =IF(T_Prestamos[[#This Row],[Situación]]="Cancelados",T_Prestamos[[#This Row],[Fecha cancelación]],TODAY())-T_Prestamos[[#This Row],[firma préstamo]] -> 938 | R13: =IF(T_Prestamos[[#This Row],[Situación]]="Cancelada","",DATEDIF(T_Prestamos[[#This Row],[firma préstamo]],TODAY(),"m")) -> 113 | S13: =IF(T_Prestamos[[#This Row],[Situación]]="Cancelados",0,IF(T_Prestamos[[#This Row],[Tipo préstamo]]="Americano",T_Prestamos[[#This Row],[Importe]],T_Prestamos[[#This Row],[Importe]]+CUMPRINC(G13/12,E13*12,F13,1,R13,0))) -> 0 | T13: =IF(T_Prestamos[[#This Row],[Situación]]="Cancelados",0,IF(T_Prestamos[[#This Row],[Tipo préstamo]]="Americano",T_Prestamos[[#This Row],[Pendiente]]*T_Prestamos[[#This Row],[% interés ordinario]],-CUMIPMT(G13/12,E13*12,F13,R13,R13+11,0))) -> 0 | U13: 0 | V13: =T_Prestamos[[#This Row],[% apertura]]*T_Prestamos[[#This Row],[Importe]] -> 0 | Y13: =IF(T_Prestamos[[#This Row],[Situación]]="Activos",IF(T_Prestamos[[#This Row],[Tipo préstamo]]="Francés",DATEDIF(T_Prestamos[[#This Row],[firma préstamo]],DATE(YEAR(TODAY()),1,1),"m"),0),0) -> 0 | Z13: =IF(T_Prestamos[[#This Row],[Situación]]="Activos",IF(T_Prestamos[[#This Row],[Tipo préstamo]]="Americano",T_Prestamos[[#This Row],[Importe]]*T_Prestamos[[#This Row],[% interés ordinario]],-CUMIPMT(T_Prestamos[[#This Row],[% interés ordinario]]/12,T_Prestamos[[#This Row],[Años]]*12,T_Prestamos[[#This Row],[Importe]],T_Prestamos[[#This Row],[Primera cuota año]],T_Prestamos[[#This Row],[Primera cuota año]]+11,0)),0) -> 0 | AA13: =IF(T_Prestamos[[#This Row],[firma préstamo]]>DATE(YEAR(TODAY())-1,MONTH(TODAY()),DAY(TODAY())),T_Prestamos[[#This Row],[Importe]]*T_Prestamos[[#This Row],[% apertura]],0) -> 0
B14: 2010 | C14: Préstamo Jaume Solè Bardalet | D14: 43151 | E14: 1 | F14: 60375 | G14: 0.15 | H14: 0.17 | J14: =IF(T_Prestamos[[#This Row],[Garantía]]="","",T_Prestamos[[#This Row],[Pendiente]]/T_Prestamos[[#This Row],[Garantía]]) | K14: Física | L14: Francés | M14: Silex | N14: Cancelados | O14: 43742 | Q14: =IF(T_Prestamos[[#This Row],[Situación]]="Cancelados",T_Prestamos[[#This Row],[Fecha cancelación]],TODAY())-T_Prestamos[[#This Row],[firma préstamo]] -> 591 | R14: =IF(T_Prestamos[[#This Row],[Situación]]="Cancelada","",DATEDIF(T_Prestamos[[#This Row],[firma préstamo]],TODAY(),"m")) -> 96 | S14: =IF(T_Prestamos[[#This Row],[Situación]]="Cancelados",0,IF(T_Prestamos[[#This Row],[Tipo préstamo]]="Americano",T_Prestamos[[#This Row],[Importe]],T_Prestamos[[#This Row],[Importe]]+CUMPRINC(G14/12,E14*12,F14,1,R14,0))) -> 0 | T14: =IF(T_Prestamos[[#This Row],[Situación]]="Cancelados",0,IF(T_Prestamos[[#This Row],[Tipo préstamo]]="Americano",T_Prestamos[[#This Row],[Pendiente]]*T_Prestamos[[#This Row],[% interés ordinario]],-CUMIPMT(G14/12,E14*12,F14,R14,R14+11,0))) -> 0 | U14: 0 | V14: =T_Prestamos[[#This Row],[% apertura]]*T_Prestamos[[#This Row],[Importe]] -> 0 | Y14: =IF(T_Prestamos[[#This Row],[Situación]]="Activos",IF(T_Prestamos[[#This Row],[Tipo préstamo]]="Francés",DATEDIF(T_Prestamos[[#This Row],[firma préstamo]],DATE(YEAR(TODAY()),1,1),"m"),0),0) -> 0 | Z14: =IF(T_Prestamos[[#This Row],[Situación]]="Activos",IF(T_Prestamos[[#This Row],[Tipo préstamo]]="Americano",T_Prestamos[[#This Row],[Importe]]*T_Prestamos[[#This Row],[% interés ordinario]],-CUMIPMT(T_Prestamos[[#This Row],[% interés ordinario]]/12,T_Prestamos[[#This Row],[Años]]*12,T_Prestamos[[#This Row],[Importe]],T_Prestamos[[#This Row],[Primera cuota año]],T_Prestamos[[#This Row],[Primera cuota año]]+11,0)),0) -> 0 | AA14: =IF(T_Prestamos[[#This Row],[firma préstamo]]>DATE(YEAR(TODAY())-1,MONTH(TODAY()),DAY(TODAY())),T_Prestamos[[#This Row],[Importe]]*T_Prestamos[[#This Row],[% apertura]],0) -> 0
B15: 2011 | C15: Préstamo Rubén Gil de Blás | D15: 43167 | E15: 5 | F15: 14000 | G15: 0.125 | H15: 0.145 | J15: =IF(T_Prestamos[[#This Row],[Garantía]]="","",T_Prestamos[[#This Row],[Pendiente]]/T_Prestamos[[#This Row],[Garantía]]) | K15: Física | L15: Francés | M15: Silex | N15: Cancelados | O15: 44855 | Q15: =IF(T_Prestamos[[#This Row],[Situación]]="Cancelados",T_Prestamos[[#This Row],[Fecha cancelación]],TODAY())-T_Prestamos[[#This Row],[firma préstamo]] -> 1688 | R15: =IF(T_Prestamos[[#This Row],[Situación]]="Cancelada","",DATEDIF(T_Prestamos[[#This Row],[firma préstamo]],TODAY(),"m")) -> 96 | S15: =IF(T_Prestamos[[#This Row],[Situación]]="Cancelados",0,IF(T_Prestamos[[#This Row],[Tipo préstamo]]="Americano",T_Prestamos[[#This Row],[Importe]],T_Prestamos[[#This Row],[Importe]]+CUMPRINC(G15/12,E15*12,F15,1,R15,0))) -> 0 | T15: =IF(T_Prestamos[[#This Row],[Situación]]="Cancelados",0,IF(T_Prestamos[[#This Row],[Tipo préstamo]]="Americano",T_Prestamos[[#This Row],[Pendiente]]*T_Prestamos[[#This Row],[% interés ordinario]],-CUMIPMT(G15/12,E15*12,F15,R15,R15+11,0))) -> 0 | U15: 0 | V15: =T_Prestamos[[#This Row],[% apertura]]*T_Prestamos[[#This Row],[Importe]] -> 0 | Y15: =IF(T_Prestamos[[#This Row],[Situación]]="Activos",IF(T_Prestamos[[#This Row],[Tipo préstamo]]="Francés",DATEDIF(T_Prestamos[[#This Row],[firma préstamo]],DATE(YEAR(TODAY()),1,1),"m"),0),0) -> 0 | Z15: =IF(T_Prestamos[[#This Row],[Situación]]="Activos",IF(T_Prestamos[[#This Row],[Tipo préstamo]]="Americano",T_Prestamos[[#This Row],[Importe]]*T_Prestamos[[#This Row],[% interés ordinario]],-CUMIPMT(T_Prestamos[[#This Row],[% interés ordinario]]/12,T_Prestamos[[#This Row],[Años]]*12,T_Prestamos[[#This Row],[Importe]],T_Prestamos[[#This Row],[Primera cuota año]],T_Prestamos[[#This Row],[Primera cuota año]]+11,0)),0) -> 0 | AA15: =IF(T_Prestamos[[#This Row],[firma préstamo]]>DATE(YEAR(TODAY())-1,MONTH(TODAY()),DAY(TODAY())),T_Prestamos[[#This Row],[Importe]]*T_Prestamos[[#This Row],[% apertura]],0) -> 0
B16: 2012 | C16: Noia - Persona física | D16: 43168 | E16: 11 | F16: 34500 | G16: 0.135 | H16: =T_Prestamos[[#This Row],[% interés ordinario]]+3% -> 0.165 | I16: 91505 | J16: =IF(T_Prestamos[[#This Row],[Garantía]]="","",T_Prestamos[[#This Row],[Pendiente]]/T_Prestamos[[#This Row],[Garantía]]) -> 0.16198557 | K16: Física | L16: Francés | M16: Silex | N16: Activos | Q16: =IF(T_Prestamos[[#This Row],[Situación]]="Cancelados",T_Prestamos[[#This Row],[Fecha cancelación]],TODAY())-T_Prestamos[[#This Row],[firma préstamo]] -> 2928 | R16: =IF(T_Prestamos[[#This Row],[Situación]]="Cancelada","",DATEDIF(T_Prestamos[[#This Row],[firma préstamo]],TODAY(),"m")) -> 96 | S16: =IF(T_Prestamos[[#This Row],[Situación]]="Cancelados",0,IF(T_Prestamos[[#This Row],[Tipo préstamo]]="Americano",T_Prestamos[[#This Row],[Importe]],T_Prestamos[[#This Row],[Importe]]+CUMPRINC(G16/12,E16*12,F16,1,R16,0))) -> 14822.49 | T16: =IF(T_Prestamos[[#This Row],[Situación]]="Cancelados",0,IF(T_Prestamos[[#This Row],[Tipo préstamo]]="Americano",T_Prestamos[[#This Row],[Pendiente]]*T_Prestamos[[#This Row],[% interés ordinario]],-CUMIPMT(G16/12,E16*12,F16,R16,R16+11,0))) -> 1789.5383 | U16: 0 | V16: =T_Prestamos[[#This Row],[% apertura]]*T_Prestamos[[#This Row],[Importe]] -> 0 | W16: Carencia 12 meses | X16: Santiago Figueiras Soñora | Y16: =IF(T_Prestamos[[#This Row],[Situación]]="Activos",IF(T_Prestamos[[#This Row],[Tipo préstamo]]="Francés",DATEDIF(T_Prestamos[[#This Row],[firma préstamo]],DATE(YEAR(TODAY()),1,1),"m"),0),0) -> 93 | Z16: =IF(T_Prestamos[[#This Row],[Situación]]="Activos",IF(T_Prestamos[[#This Row],[Tipo préstamo]]="Americano",T_Prestamos[[#This Row],[Importe]]*T_Prestamos[[#This Row],[% interés ordinario]],-CUMIPMT(T_Prestamos[[#This Row],[% interés ordinario]]/12,T_Prestamos[[#This Row],[Años]]*12,T_Prestamos[[#This Row],[Importe]],T_Prestamos[[#This Row],[Primera cuota año]],T_Prestamos[[#This Row],[Primera cuota año]]+11,0)),0) -> 1929.6933 | AA16: =IF(T_Prestamos[[#This Row],[firma préstamo]]>DATE(YEAR(TODAY())-1,MONTH(TODAY()),DAY(TODAY())),T_Prestamos[[#This Row],[Importe]]*T_Prestamos[[#This Row],[% apertura]],0) -> 0
B17: 2013 | C17: Préstamo Gestión y Trámites - David Ferrer | D17: 42940 | E17: 3 | F17: 37000 | G17: 0.02 | H17: =T_Prestamos[[#This Row],[% interés ordinario]]+3% -> 0.05 | J17: =IF(T_Prestamos[[#This Row],[Garantía]]="","",T_Prestamos[[#This Row],[Pendiente]]/T_Prestamos[[#This Row],[Garantía]]) | K17: Física | L17: Americano | M17: Silex | N17: Cancelados | O17: 43650 | Q17: =IF(T_Prestamos[[#This Row],[Situación]]="Cancelados",T_Prestamos[[#This Row],[Fecha cancelación]],TODAY())-T_Prestamos[[#This Row],[firma préstamo]] -> 710 | R17: =IF(T_Prestamos[[#This Row],[Situación]]="Cancelada","",DATEDIF(T_Prestamos[[#This Row],[firma préstamo]],TODAY(),"m")) -> 103 | S17: =IF(T_Prestamos[[#This Row],[Situación]]="Cancelados",0,IF(T_Prestamos[[#This Row],[Tipo préstamo]]="Americano",T_Prestamos[[#This Row],[Importe]],T_Prestamos[[#This Row],[Importe]]+CUMPRINC(G17/12,E17*12,F17,1,R17,0))) -> 0 | T17: =IF(T_Prestamos[[#This Row],[Situación]]="Cancelados",0,IF(T_Prestamos[[#This Row],[Tipo préstamo]]="Americano",T_Prestamos[[#This Row],[Pendiente]]*T_Prestamos[[#This Row],[% interés ordinario]],-CUMIPMT(G17/12,E17*12,F17,R17,R17+11,0))) -> 0 | U17: 0 | V17: =T_Prestamos[[#This Row],[% apertura]]*T_Prestamos[[#This Row],[Importe]] -> 0 | Y17: =IF(T_Prestamos[[#This Row],[Situación]]="Activos",IF(T_Prestamos[[#This Row],[Tipo préstamo]]="Francés",DATEDIF(T_Prestamos[[#This Row],[firma préstamo]],DATE(YEAR(TODAY()),1,1),"m"),0),0) -> 0 | Z17: =IF(T_Prestamos[[#This Row],[Situación]]="Activos",IF(T_Prestamos[[#This Row],[Tipo préstamo]]="Americano",T_Prestamos[[#This Row],[Importe]]*T_Prestamos[[#This Row],[% interés ordinario]],-CUMIPMT(T_Prestamos[[#This Row],[% interés ordinario]]/12,T_Prestamos[[#This Row],[Años]]*12,T_Prestamos[[#This Row],[Importe]],T_Prestamos[[#This Row],[Primera cuota año]],T_Prestamos[[#This Row],[Primera cuota año]]+11,0)),0) -> 0 | AA17: =IF(T_Prestamos[[#This Row],[firma préstamo]]>DATE(YEAR(TODAY())-1,MONTH(TODAY()),DAY(TODAY())),T_Prestamos[[#This Row],[Importe]]*T_Prestamos[[#This Row],[% apertura]],0) -> 0
B18: 2014 | C18: Préstamo José Dominguez Caballero | D18: 43179 | E18: 10 | F18: 20000 | G18: 0.135 | H18: 0.155 | J18: =IF(T_Prestamos[[#This Row],[Garantía]]="","",T_Prestamos[[#This Row],[Pendiente]]/T_Prestamos[[#This Row],[Garantía]]) | K18: Física | L18: Francés | M18: Silex | N18: Cancelados | O18: 44978 | Q18: =IF(T_Prestamos[[#This Row],[Situación]]="Cancelados",T_Prestamos[[#This Row],[Fecha cancelación]],TODAY())-T_Prestamos[[#This Row],[firma préstamo]] -> 1799 | R18: =IF(T_Prestamos[[#This Row],[Situación]]="Cancelada","",DATEDIF(T_Prestamos[[#This Row],[firma préstamo]],TODAY(),"m")) -> 95 | S18: =IF(T_Prestamos[[#This Row],[Situación]]="Cancelados",0,IF(T_Prestamos[[#This Row],[Tipo préstamo]]="Americano",T_Prestamos[[#This Row],[Importe]],T_Prestamos[[#This Row],[Importe]]+CUMPRINC(G18/12,E18*12,F18,1,R18,0))) -> 0 | T18: =IF(T_Prestamos[[#This Row],[Situación]]="Cancelados",0,IF(T_Prestamos[[#This Row],[Tipo préstamo]]="Americano",T_Prestamos[[#This Row],[Pendiente]]*T_Prestamos[[#This Row],[% interés ordinario]],-CUMIPMT(G18/12,E18*12,F18,R18,R18+11,0))) -> 0 | U18: 0 | V18: =T_Prestamos[[#This Row],[% apertura]]*T_Prestamos[[#This Row],[Importe]] -> 0 | Y18: =IF(T_Prestamos[[#This Row],[Situación]]="Activos",IF(T_Prestamos[[#This Row],[Tipo préstamo]]="Francés",DATEDIF(T_Prestamos[[#This Row],[firma préstamo]],DATE(YEAR(TODAY()),1,1),"m"),0),0) -> 0 | Z18: =IF(T_Prestamos[[#This Row],[Situación]]="Activos",IF(T_Prestamos[[#This Row],[Tipo préstamo]]="Americano",T_Prestamos[[#This Row],[Importe]]*T_Prestamos[[#This Row],[% interés ordinario]],-CUMIPMT(T_Prestamos[[#This Row],[% interés ordinario]]/12,T_Prestamos[[#This Row],[Años]]*12,T_Prestamos[[#This Row],[Importe]],T_Prestamos[[#This Row],[Primera cuota año]],T_Prestamos[[#This Row],[Primera cuota año]]+11,0)),0) -> 0 | AA18: =IF(T_Prestamos[[#This Row],[firma préstamo]]>DATE(YEAR(TODAY())-1,MONTH(TODAY()),DAY(TODAY())),T_Prestamos[[#This Row],[Importe]]*T_Prestamos[[#This Row],[% apertura]],0) -> 0
B19: 2015 | C19: Préstamo M.Teresa Faure y David Zamora | D19: 43208 | E19: 10 | F19: 36500 | G19: 0.125 | H19: 0.145 | J19: =IF(T_Prestamos[[#This Row],[Garantía]]="","",T_Prestamos[[#This Row],[Pendiente]]/T_Prestamos[[#This Row],[Garantía]]) | K19: Física | L19: Francés | M19: Silex | N19: Cancelados | O19: 43448 | Q19: =IF(T_Prestamos[[#This Row],[Situación]]="Cancelados",T_Prestamos[[#This Row],[Fecha cancelación]],TODAY())-T_Prestamos[[#This Row],[firma préstamo]] -> 240 | R19: =IF(T_Prestamos[[#This Row],[Situación]]="Cancelada","",DATEDIF(T_Prestamos[[#This Row],[firma préstamo]],TODAY(),"m")) -> 94 | S19: =IF(T_Prestamos[[#This Row],[Situación]]="Cancelados",0,IF(T_Prestamos[[#This Row],[Tipo préstamo]]="Americano",T_Prestamos[[#This Row],[Importe]],T_Prestamos[[#This Row],[Importe]]+CUMPRINC(G19/12,E19*12,F19,1,R19,0))) -> 0 | T19: =IF(T_Prestamos[[#This Row],[Situación]]="Cancelados",0,IF(T_Prestamos[[#This Row],[Tipo préstamo]]="Americano",T_Prestamos[[#This Row],[Pendiente]]*T_Prestamos[[#This Row],[% interés ordinario]],-CUMIPMT(G19/12,E19*12,F19,R19,R19+11,0))) -> 0 | U19: 0 | V19: =T_Prestamos[[#This Row],[% apertura]]*T_Prestamos[[#This Row],[Importe]] -> 0 | Y19: =IF(T_Prestamos[[#This Row],[Situación]]="Activos",IF(T_Prestamos[[#This Row],[Tipo préstamo]]="Francés",DATEDIF(T_Prestamos[[#This Row],[firma préstamo]],DATE(YEAR(TODAY()),1,1),"m"),0),0) -> 0 | Z19: =IF(T_Prestamos[[#This Row],[Situación]]="Activos",IF(T_Prestamos[[#This Row],[Tipo préstamo]]="Americano",T_Prestamos[[#This Row],[Importe]]*T_Prestamos[[#This Row],[% interés ordinario]],-CUMIPMT(T_Prestamos[[#This Row],[% interés ordinario]]/12,T_Prestamos[[#This Row],[Años]]*12,T_Prestamos[[#This Row],[Importe]],T_Prestamos[[#This Row],[Primera cuota año]],T_Prestamos[[#This Row],[Primera cuota año]]+11,0)),0) -> 0 | AA19: =IF(T_Prestamos[[#This Row],[firma préstamo]]>DATE(YEAR(TODAY())-1,MONTH(TODAY()),DAY(TODAY())),T_Prestamos[[#This Row],[Importe]]*T_Prestamos[[#This Row],[% apertura]],0) -> 0
B20: 2016 | C20: Lorca - Murcia - Persona física | D20: 43279 | E20: 10 | F20: 24500 | G20: 0.13 | H20: =T_Prestamos[[#This Row],[% interés ordinario]]+3% -> 0.16 | I20: 89443 | J20: =IF(T_Prestamos[[#This Row],[Garantía]]="","",T_Prestamos[[#This Row],[Pendiente]]/T_Prestamos[[#This Row],[Garantía]]) -> 0.098323889 | K20: Física | L20: Francés | M20: Silex | N20: Activos | Q20: =IF(T_Prestamos[[#This Row],[Situación]]="Cancelados",T_Prestamos[[#This Row],[Fecha cancelación]],TODAY())-T_Prestamos[[#This Row],[firma préstamo]] -> 2817 | R20: =IF(T_Prestamos[[#This Row],[Situación]]="Cancelada","",DATEDIF(T_Prestamos[[#This Row],[firma préstamo]],TODAY(),"m")) -> 92 | S20: =IF(T_Prestamos[[#This Row],[Situación]]="Cancelados",0,IF(T_Prestamos[[#This Row],[Tipo préstamo]]="Americano",T_Prestamos[[#This Row],[Importe]],T_Prestamos[[#This Row],[Importe]]+CUMPRINC(G20/12,E20*12,F20,1,R20,0))) -> 8794.3836 | T20: =IF(T_Prestamos[[#This Row],[Situación]]="Cancelados",0,IF(T_Prestamos[[#This Row],[Tipo préstamo]]="Americano",T_Prestamos[[#This Row],[Pendiente]]*T_Prestamos[[#This Row],[% interés ordinario]],-CUMIPMT(G20/12,E20*12,F20,R20,R20+11,0))) -> 979.61913 | U20: 0 | V20: =T_Prestamos[[#This Row],[% apertura]]*T_Prestamos[[#This Row],[Importe]] -> 0 | X20: José Zamora Molina | Y20: =IF(T_Prestamos[[#This Row],[Situación]]="Activos",IF(T_Prestamos[[#This Row],[Tipo préstamo]]="Francés",DATEDIF(T_Prestamos[[#This Row],[firma préstamo]],DATE(YEAR(TODAY()),1,1),"m"),0),0) -> 90 | Z20: =IF(T_Prestamos[[#This Row],[Situación]]="Activos",IF(T_Prestamos[[#This Row],[Tipo préstamo]]="Americano",T_Prestamos[[#This Row],[Importe]]*T_Prestamos[[#This Row],[% interés ordinario]],-CUMIPMT(T_Prestamos[[#This Row],[% interés ordinario]]/12,T_Prestamos[[#This Row],[Años]]*12,T_Prestamos[[#This Row],[Importe]],T_Prestamos[[#This Row],[Primera cuota año]],T_Prestamos[[#This Row],[Primera cuota año]]+11,0)),0) -> 1052.3215 | AA20: =IF(T_Prestamos[[#This Row],[firma préstamo]]>DATE(YEAR(TODAY())-1,MONTH(TODAY()),DAY(TODAY())),T_Prestamos[[#This Row],[Importe]]*T_Prestamos[[#This Row],[% apertura]],0) -> 0
B21: 2017 | C21: Préstamo Jose Antonio García Mañanes | D21: 43208 | E21: 10 | F21: 36500 | G21: 0.125 | H21: 0.145 | J21: =IF(T_Prestamos[[#This Row],[Garantía]]="","",T_Prestamos[[#This Row],[Pendiente]]/T_Prestamos[[#This Row],[Garantía]]) | K21: Física | L21: Francés | M21: Silex | N21: Cancelados | O21: 43448 | Q21: =IF(T_Prestamos[[#This Row],[Situación]]="Cancelados",T_Prestamos[[#This Row],[Fecha cancelación]],TODAY())-T_Prestamos[[#This Row],[firma préstamo]] -> 240 | R21: =IF(T_Prestamos[[#This Row],[Situación]]="Cancelada","",DATEDIF(T_Prestamos[[#This Row],[firma préstamo]],TODAY(),"m")) -> 94 | S21: =IF(T_Prestamos[[#This Row],[Situación]]="Cancelados",0,IF(T_Prestamos[[#This Row],[Tipo préstamo]]="Americano",T_Prestamos[[#This Row],[Importe]],T_Prestamos[[#This Row],[Importe]]+CUMPRINC(G21/12,E21*12,F21,1,R21,0))) -> 0 | T21: =IF(T_Prestamos[[#This Row],[Situación]]="Cancelados",0,IF(T_Prestamos[[#This Row],[Tipo préstamo]]="Americano",T_Prestamos[[#This Row],[Pendiente]]*T_Prestamos[[#This Row],[% interés ordinario]],-CUMIPMT(G21/12,E21*12,F21,R21,R21+11,0))) -> 0 | U21: 0 | V21: =T_Prestamos[[#This Row],[% apertura]]*T_Prestamos[[#This Row],[Importe]] -> 0 | Y21: =IF(T_Prestamos[[#This Row],[Situación]]="Activos",IF(T_Prestamos[[#This Row],[Tipo préstamo]]="Francés",DATEDIF(T_Prestamos[[#This Row],[firma préstamo]],DATE(YEAR(TODAY()),1,1),"m"),0),0) -> 0 | Z21: =IF(T_Prestamos[[#This Row],[Situación]]="Activos",IF(T_Prestamos[[#This Row],[Tipo préstamo]]="Americano",T_Prestamos[[#This Row],[Importe]]*T_Prestamos[[#This Row],[% interés ordinario]],-CUMIPMT(T_Prestamos[[#This Row],[% interés ordinario]]/12,T_Prestamos[[#This Row],[Años]]*12,T_Prestamos[[#This Row],[Importe]],T_Prestamos[[#This Row],[Primera cuota año]],T_Prestamos[[#This Row],[Primera cuota año]]+11,0)),0) -> 0 | AA21: =IF(T_Prestamos[[#This Row],[firma préstamo]]>DATE(YEAR(TODAY())-1,MONTH(TODAY()),DAY(TODAY())),T_Prestamos[[#This Row],[Importe]]*T_Prestamos[[#This Row],[% apertura]],0) -> 0
B22: 2018 | C22: Préstamo Antonio Torres Marmol | D22: 43300 | E22: 10 | F22: 14500 | G22: 0.125 | H22: 0.145 | J22: =IF(T_Prestamos[[#This Row],[Garantía]]="","",T_Prestamos[[#This Row],[Pendiente]]/T_Prestamos[[#This Row],[Garantía]]) | K22: Física | L22: Francés | M22: Silex | N22: Cancelados | O22: 43796 | Q22: =IF(T_Prestamos[[#This Row],[Situación]]="Cancelados",T_Prestamos[[#This Row],[Fecha cancelación]],TODAY())-T_Prestamos[[#This Row],[firma préstamo]] -> 496 | R22: =IF(T_Prestamos[[#This Row],[Situación]]="Cancelada","",DATEDIF(T_Prestamos[[#This Row],[firma préstamo]],TODAY(),"m")) -> 91 | S22: =IF(T_Prestamos[[#This Row],[Situación]]="Cancelados",0,IF(T_Prestamos[[#This Row],[Tipo préstamo]]="Americano",T_Prestamos[[#This Row],[Importe]],T_Prestamos[[#This Row],[Importe]]+CUMPRINC(G22/12,E22*12,F22,1,R22,0))) -> 0 | T22: =IF(T_Prestamos[[#This Row],[Situación]]="Cancelados",0,IF(T_Prestamos[[#This Row],[Tipo préstamo]]="Americano",T_Prestamos[[#This Row],[Pendiente]]*T_Prestamos[[#This Row],[% interés ordinario]],-CUMIPMT(G22/12,E22*12,F22,R22,R22+11,0))) -> 0 | U22: 0 | V22: =T_Prestamos[[#This Row],[% apertura]]*T_Prestamos[[#This Row],[Importe]] -> 0 | Y22: =IF(T_Prestamos[[#This Row],[Situación]]="Activos",IF(T_Prestamos[[#This Row],[Tipo préstamo]]="Francés",DATEDIF(T_Prestamos[[#This Row],[firma préstamo]],DATE(YEAR(TODAY()),1,1),"m"),0),0) -> 0 | Z22: =IF(T_Prestamos[[#This Row],[Situación]]="Activos",IF(T_Prestamos[[#This Row],[Tipo préstamo]]="Americano",T_Prestamos[[#This Row],[Importe]]*T_Prestamos[[#This Row],[% interés ordinario]],-CUMIPMT(T_Prestamos[[#This Row],[% interés ordinario]]/12,T_Prestamos[[#This Row],[Años]]*12,T_Prestamos[[#This Row],[Importe]],T_Prestamos[[#This Row],[Primera cuota año]],T_Prestamos[[#This Row],[Primera cuota año]]+11,0)),0) -> 0 | AA22: =IF(T_Prestamos[[#This Row],[firma préstamo]]>DATE(YEAR(TODAY())-1,MONTH(TODAY()),DAY(TODAY())),T_Prestamos[[#This Row],[Importe]]*T_Prestamos[[#This Row],[% apertura]],0) -> 0
B23: 2019 | C23: Préstamo Jose Antonio López Oñate | D23: 43319 | E23: 10 | F23: 30500 | G23: 0.125 | H23: 0.145 | I23: 110101 | J23: =IF(T_Prestamos[[#This Row],[Garantía]]="","",T_Prestamos[[#This Row],[Pendiente]]/T_Prestamos[[#This Row],[Garantía]]) -> 0.10104167 | K23: Física | L23: Francés | M23: Silex | N23: Judicializados | Q23: =IF(T_Prestamos[[#This Row],[Situación]]="Cancelados",T_Prestamos[[#This Row],[Fecha cancelación]],TODAY())-T_Prestamos[[#This Row],[firma préstamo]] -> 2777 | R23: =IF(T_Prestamos[[#This Row],[Situación]]="Cancelada","",DATEDIF(T_Prestamos[[#This Row],[firma préstamo]],TODAY(),"m")) -> 91 | S23: =IF(T_Prestamos[[#This Row],[Situación]]="Cancelados",0,IF(T_Prestamos[[#This Row],[Tipo préstamo]]="Americano",T_Prestamos[[#This Row],[Importe]],T_Prestamos[[#This Row],[Importe]]+CUMPRINC(G23/12,E23*12,F23,1,R23,0))) -> 11124.789 | T23: =IF(T_Prestamos[[#This Row],[Situación]]="Cancelados",0,IF(T_Prestamos[[#This Row],[Tipo préstamo]]="Americano",T_Prestamos[[#This Row],[Pendiente]]*T_Prestamos[[#This Row],[% interés ordinario]],-CUMIPMT(G23/12,E23*12,F23,R23,R23+11,0))) -> 1198.5774 | U23: 0 | V23: =T_Prestamos[[#This Row],[% apertura]]*T_Prestamos[[#This Row],[Importe]] -> 0 | W23: En reclamación judicial | Y23: =IF(T_Prestamos[[#This Row],[Situación]]="Activos",IF(T_Prestamos[[#This Row],[Tipo préstamo]]="Francés",DATEDIF(T_Prestamos[[#This Row],[firma préstamo]],DATE(YEAR(TODAY()),1,1),"m"),0),0) -> 0 | Z23: =IF(T_Prestamos[[#This Row],[Situación]]="Activos",IF(T_Prestamos[[#This Row],[Tipo préstamo]]="Americano",T_Prestamos[[#This Row],[Importe]]*T_Prestamos[[#This Row],[% interés ordinario]],-CUMIPMT(T_Prestamos[[#This Row],[% interés ordinario]]/12,T_Prestamos[[#This Row],[Años]]*12,T_Prestamos[[#This Row],[Importe]],T_Prestamos[[#This Row],[Primera cuota año]],T_Prestamos[[#This Row],[Primera cuota año]]+11,0)),0) -> 0 | AA23: =IF(T_Prestamos[[#This Row],[firma préstamo]]>DATE(YEAR(TODAY())-1,MONTH(TODAY()),DAY(TODAY())),T_Prestamos[[#This Row],[Importe]]*T_Prestamos[[#This Row],[% apertura]],0) -> 0
B24: 2020 | C24: Préstamo Ana Isabel Otegui Aramburu | D24: 43353 | E24: 15 | F24: 19300 | G24: 0.125 | H24: 0.145 | J24: =IF(T_Prestamos[[#This Row],[Garantía]]="","",T_Prestamos[[#This Row],[Pendiente]]/T_Prestamos[[#This Row],[Garantía]]) | K24: Física | L24: Francés | M24: Silex | N24: Cancelados | O24: 43586 | Q24: =IF(T_Prestamos[[#This Row],[Situación]]="Cancelados",T_Prestamos[[#This Row],[Fecha cancelación]],TODAY())-T_Prestamos[[#This Row],[firma préstamo]] -> 233 | R24: =IF(T_Prestamos[[#This Row],[Situación]]="Cancelada","",DATEDIF(T_Prestamos[[#This Row],[firma préstamo]],TODAY(),"m")) -> 90 | S24: =IF(T_Prestamos[[#This Row],[Situación]]="Cancelados",0,IF(T_Prestamos[[#This Row],[Tipo préstamo]]="Americano",T_Prestamos[[#This Row],[Importe]],T_Prestamos[[#This Row],[Importe]]+CUMPRINC(G24/12,E24*12,F24,1,R24,0))) -> 0 | T24: =IF(T_Prestamos[[#This Row],[Situación]]="Cancelados",0,IF(T_Prestamos[[#This Row],[Tipo préstamo]]="Americano",T_Prestamos[[#This Row],[Pendiente]]*T_Prestamos[[#This Row],[% interés ordinario]],-CUMIPMT(G24/12,E24*12,F24,R24,R24+11,0))) -> 0 | U24: 0 | V24: =T_Prestamos[[#This Row],[% apertura]]*T_Prestamos[[#This Row],[Importe]] -> 0 | Y24: =IF(T_Prestamos[[#This Row],[Situación]]="Activos",IF(T_Prestamos[[#This Row],[Tipo préstamo]]="Francés",DATEDIF(T_Prestamos[[#This Row],[firma préstamo]],DATE(YEAR(TODAY()),1,1),"m"),0),0) -> 0 | Z24: =IF(T_Prestamos[[#This Row],[Situación]]="Activos",IF(T_Prestamos[[#This Row],[Tipo préstamo]]="Americano",T_Prestamos[[#This Row],[Importe]]*T_Prestamos[[#This Row],[% interés ordinario]],-CUMIPMT(T_Prestamos[[#This Row],[% interés ordinario]]/12,T_Prestamos[[#This Row],[Años]]*12,T_Prestamos[[#This Row],[Importe]],T_Prestamos[[#This Row],[Primera cuota año]],T_Prestamos[[#This Row],[Primera cuota año]]+11,0)),0) -> 0 | AA24: =IF(T_Prestamos[[#This Row],[firma préstamo]]>DATE(YEAR(TODAY())-1,MONTH(TODAY()),DAY(TODAY())),T_Prestamos[[#This Row],[Importe]]*T_Prestamos[[#This Row],[% apertura]],0) -> 0
B25: 2021 | C25: Préstamo Florentina González Martos | D25: 43375 | E25: 10 | F25: 15000 | G25: 0.135 | H25: 0.155 | I25: 111078 | J25: =IF(T_Prestamos[[#This Row],[Garantía]]="","",T_Prestamos[[#This Row],[Pendiente]]/T_Prestamos[[#This Row],[Garantía]]) -> 0.053565712 | K25: Física | L25: Francés | M25: Silex | N25: Judicializados | Q25: =IF(T_Prestamos[[#This Row],[Situación]]="Cancelados",T_Prestamos[[#This Row],[Fecha cancelación]],TODAY())-T_Prestamos[[#This Row],[firma préstamo]] -> 2721 | R25: =IF(T_Prestamos[[#This Row],[Situación]]="Cancelada","",DATEDIF(T_Prestamos[[#This Row],[firma préstamo]],TODAY(),"m")) -> 89 | S25: =IF(T_Prestamos[[#This Row],[Situación]]="Cancelados",0,IF(T_Prestamos[[#This Row],[Tipo préstamo]]="Americano",T_Prestamos[[#This Row],[Importe]],T_Prestamos[[#This Row],[Importe]]+CUMPRINC(G25/12,E25*12,F25,1,R25,0))) -> 5949.9722 | T25: =IF(T_Prestamos[[#This Row],[Situación]]="Cancelados",0,IF(T_Prestamos[[#This Row],[Tipo préstamo]]="Americano",T_Prestamos[[#This Row],[Pendiente]]*T_Prestamos[[#This Row],[% interés ordinario]],-CUMIPMT(G25/12,E25*12,F25,R25,R25+11,0))) -> 701.68132 | U25: 0 | V25: =T_Prestamos[[#This Row],[% apertura]]*T_Prestamos[[#This Row],[Importe]] -> 0 | W25: En reclamación judicial | Y25: =IF(T_Prestamos[[#This Row],[Situación]]="Activos",IF(T_Prestamos[[#This Row],[Tipo préstamo]]="Francés",DATEDIF(T_Prestamos[[#This Row],[firma préstamo]],DATE(YEAR(TODAY()),1,1),"m"),0),0) -> 0 | Z25: =IF(T_Prestamos[[#This Row],[Situación]]="Activos",IF(T_Prestamos[[#This Row],[Tipo préstamo]]="Americano",T_Prestamos[[#This Row],[Importe]]*T_Prestamos[[#This Row],[% interés ordinario]],-CUMIPMT(T_Prestamos[[#This Row],[% interés ordinario]]/12,T_Prestamos[[#This Row],[Años]]*12,T_Prestamos[[#This Row],[Importe]],T_Prestamos[[#This Row],[Primera cuota año]],T_Prestamos[[#This Row],[Primera cuota año]]+11,0)),0) -> 0 | AA25: =IF(T_Prestamos[[#This Row],[firma préstamo]]>DATE(YEAR(TODAY())-1,MONTH(TODAY()),DAY(TODAY())),T_Prestamos[[#This Row],[Importe]]*T_Prestamos[[#This Row],[% apertura]],0) -> 0
B26: 2022 | C26: Préstamo Victor Espejo Gines | D26: 43375 | E26: 15 | F26: 18500 | G26: 0.13 | H26: 0.15 | J26: =IF(T_Prestamos[[#This Row],[Garantía]]="","",T_Prestamos[[#This Row],[Pendiente]]/T_Prestamos[[#This Row],[Garantía]]) | K26: Física | L26: Francés | M26: Silex | N26: Cancelados | O26: 43670 | Q26: =IF(T_Prestamos[[#This Row],[Situación]]="Cancelados",T_Prestamos[[#This Row],[Fecha cancelación]],TODAY())-T_Prestamos[[#This Row],[firma préstamo]] -> 295 | R26: =IF(T_Prestamos[[#This Row],[Situación]]="Cancelada","",DATEDIF(T_Prestamos[[#This Row],[firma préstamo]],TODAY(),"m")) -> 89 | S26: =IF(T_Prestamos[[#This Row],[Situación]]="Cancelados",0,IF(T_Prestamos[[#This Row],[Tipo préstamo]]="Americano",T_Prestamos[[#This Row],[Importe]],T_Prestamos[[#This Row],[Importe]]+CUMPRINC(G26/12,E26*12,F26,1,R26,0))) -> 0 | T26: =IF(T_Prestamos[[#This Row],[Situación]]="Cancelados",0,IF(T_Prestamos[[#This Row],[Tipo préstamo]]="Americano",T_Prestamos[[#This Row],[Pendiente]]*T_Prestamos[[#This Row],[% interés ordinario]],-CUMIPMT(G26/12,E26*12,F26,R26,R26+11,0))) -> 0 | U26: 0 | V26: =T_Prestamos[[#This Row],[% apertura]]*T_Prestamos[[#This Row],[Importe]] -> 0 | Y26: =IF(T_Prestamos[[#This Row],[Situación]]="Activos",IF(T_Prestamos[[#This Row],[Tipo préstamo]]="Francés",DATEDIF(T_Prestamos[[#This Row],[firma préstamo]],DATE(YEAR(TODAY()),1,1),"m"),0),0) -> 0 | Z26: =IF(T_Prestamos[[#This Row],[Situación]]="Activos",IF(T_Prestamos[[#This Row],[Tipo préstamo]]="Americano",T_Prestamos[[#This Row],[Importe]]*T_Prestamos[[#This Row],[% interés ordinario]],-CUMIPMT(T_Prestamos[[#This Row],[% interés ordinario]]/12,T_Prestamos[[#This Row],[Años]]*12,T_Prestamos[[#This Row],[Importe]],T_Prestamos[[#This Row],[Primera cuota año]],T_Prestamos[[#This Row],[Primera cuota año]]+11,0)),0) -> 0 | AA26: =IF(T_Prestamos[[#This Row],[firma préstamo]]>DATE(YEAR(TODAY())-1,MONTH(TODAY()),DAY(TODAY())),T_Prestamos[[#This Row],[Importe]]*T_Prestamos[[#This Row],[% apertura]],0) -> 0
B27: 2023 | C27: 2º Préstamo Juliana Joval Esque | D27: 43382 | E27: 15 | F27: 27990.94 | G27: 0.15 | H27: 0.17 | J27: =IF(T_Prestamos[[#This Row],[Garantía]]="","",T_Prestamos[[#This Row],[Pendiente]]/T_Prestamos[[#This Row],[Garantía]]) | K27: Física | L27: Francés | M27: Silex | N27: Cancelados | O27: 45007 | Q27: =IF(T_Prestamos[[#This Row],[Situación]]="Cancelados",T_Prestamos[[#This Row],[Fecha cancelación]],TODAY())-T_Prestamos[[#This Row],[firma préstamo]] -> 1625 | R27: =IF(T_Prestamos[[#This Row],[Situación]]="Cancelada","",DATEDIF(T_Prestamos[[#This Row],[firma préstamo]],TODAY(),"m")) -> 89 | S27: =IF(T_Prestamos[[#This Row],[Situación]]="Cancelados",0,IF(T_Prestamos[[#This Row],[Tipo préstamo]]="Americano",T_Prestamos[[#This Row],[Importe]],T_Prestamos[[#This Row],[Importe]]+CUMPRINC(G27/12,E27*12,F27,1,R27,0))) -> 0 | T27: =IF(T_Prestamos[[#This Row],[Situación]]="Cancelados",0,IF(T_Prestamos[[#This Row],[Tipo préstamo]]="Americano",T_Prestamos[[#This Row],[Pendiente]]*T_Prestamos[[#This Row],[% interés ordinario]],-CUMIPMT(G27/12,E27*12,F27,R27,R27+11,0))) -> 0 | U27: 0 | V27: =T_Prestamos[[#This Row],[% apertura]]*T_Prestamos[[#This Row],[Importe]] -> 0 | Y27: =IF(T_Prestamos[[#This Row],[Situación]]="Activos",IF(T_Prestamos[[#This Row],[Tipo préstamo]]="Francés",DATEDIF(T_Prestamos[[#This Row],[firma préstamo]],DATE(YEAR(TODAY()),1,1),"m"),0),0) -> 0 | Z27: =IF(T_Prestamos[[#This Row],[Situación]]="Activos",IF(T_Prestamos[[#This Row],[Tipo préstamo]]="Americano",T_Prestamos[[#This Row],[Importe]]*T_Prestamos[[#This Row],[% interés ordinario]],-CUMIPMT(T_Prestamos[[#This Row],[% interés ordinario]]/12,T_Prestamos[[#This Row],[Años]]*12,T_Prestamos[[#This Row],[Importe]],T_Prestamos[[#This Row],[Primera cuota año]],T_Prestamos[[#This Row],[Primera cuota año]]+11,0)),0) -> 0 | AA27: =IF(T_Prestamos[[#This Row],[firma préstamo]]>DATE(YEAR(TODAY())-1,MONTH(TODAY()),DAY(TODAY())),T_Prestamos[[#This Row],[Importe]]*T_Prestamos[[#This Row],[% apertura]],0) -> 0
B28: 2024 | C28: Préstamo Gustavo Alberto Fernández de la Puebla | D28: 43503 | E28: 10 | F28: 20000 | G28: 0.125 | H28: 0.145 | J28: =IF(T_Prestamos[[#This Row],[Garantía]]="","",T_Prestamos[[#This Row],[Pendiente]]/T_Prestamos[[#This Row],[Garantía]]) | K28: Física | L28: Francés | M28: Silex | N28: Cancelados | O28: 44742 | Q28: =IF(T_Prestamos[[#This Row],[Situación]]="Cancelados",T_Prestamos[[#This Row],[Fecha cancelación]],TODAY())-T_Prestamos[[#This Row],[firma préstamo]] -> 1239 | R28: =IF(T_Prestamos[[#This Row],[Situación]]="Cancelada","",DATEDIF(T_Prestamos[[#This Row],[firma préstamo]],TODAY(),"m")) -> 85 | S28: =IF(T_Prestamos[[#This Row],[Situación]]="Cancelados",0,IF(T_Prestamos[[#This Row],[Tipo préstamo]]="Americano",T_Prestamos[[#This Row],[Importe]],T_Prestamos[[#This Row],[Importe]]+CUMPRINC(G28/12,E28*12,F28,1,R28,0))) -> 0 | T28: =IF(T_Prestamos[[#This Row],[Situación]]="Cancelados",0,IF(T_Prestamos[[#This Row],[Tipo préstamo]]="Americano",T_Prestamos[[#This Row],[Pendiente]]*T_Prestamos[[#This Row],[% interés ordinario]],-CUMIPMT(G28/12,E28*12,F28,R28,R28+11,0))) -> 0 | U28: 0 | V28: =T_Prestamos[[#This Row],[% apertura]]*T_Prestamos[[#This Row],[Importe]] -> 0 | Y28: =IF(T_Prestamos[[#This Row],[Situación]]="Activos",IF(T_Prestamos[[#This Row],[Tipo préstamo]]="Francés",DATEDIF(T_Prestamos[[#This Row],[firma préstamo]],DATE(YEAR(TODAY()),1,1),"m"),0),0) -> 0 | Z28: =IF(T_Prestamos[[#This Row],[Situación]]="Activos",IF(T_Prestamos[[#This Row],[Tipo préstamo]]="Americano",T_Prestamos[[#This Row],[Importe]]*T_Prestamos[[#This Row],[% interés ordinario]],-CUMIPMT(T_Prestamos[[#This Row],[% interés ordinario]]/12,T_Prestamos[[#This Row],[Años]]*12,T_Prestamos[[#This Row],[Importe]],T_Prestamos[[#This Row],[Primera cuota año]],T_Prestamos[[#This Row],[Primera cuota año]]+11,0)),0) -> 0 | AA28: =IF(T_Prestamos[[#This Row],[firma préstamo]]>DATE(YEAR(TODAY())-1,MONTH(TODAY()),DAY(TODAY())),T_Prestamos[[#This Row],[Importe]]*T_Prestamos[[#This Row],[% apertura]],0) -> 0
B29: 2025 | C29: Préstamo Concepción Saiz Saiz | D29: 43503 | E29: 10 | F29: 11100 | G29: 0.125 | H29: 0.145 | J29: =IF(T_Prestamos[[#This Row],[Garantía]]="","",T_Prestamos[[#This Row],[Pendiente]]/T_Prestamos[[#This Row],[Garantía]]) | K29: Física | L29: Francés | M29: Silex | N29: Cancelados | O29: 44134 | Q29: =IF(T_Prestamos[[#This Row],[Situación]]="Cancelados",T_Prestamos[[#This Row],[Fecha cancelación]],TODAY())-T_Prestamos[[#This Row],[firma préstamo]] -> 631 | R29: =IF(T_Prestamos[[#This Row],[Situación]]="Cancelada","",DATEDIF(T_Prestamos[[#This Row],[firma préstamo]],TODAY(),"m")) -> 85 | S29: =IF(T_Prestamos[[#This Row],[Situación]]="Cancelados",0,IF(T_Prestamos[[#This Row],[Tipo préstamo]]="Americano",T_Prestamos[[#This Row],[Importe]],T_Prestamos[[#This Row],[Importe]]+CUMPRINC(G29/12,E29*12,F29,1,R29,0))) -> 0 | T29: =IF(T_Prestamos[[#This Row],[Situación]]="Cancelados",0,IF(T_Prestamos[[#This Row],[Tipo préstamo]]="Americano",T_Prestamos[[#This Row],[Pendiente]]*T_Prestamos[[#This Row],[% interés ordinario]],-CUMIPMT(G29/12,E29*12,F29,R29,R29+11,0))) -> 0 | U29: 0 | V29: =T_Prestamos[[#This Row],[% apertura]]*T_Prestamos[[#This Row],[Importe]] -> 0 | Y29: =IF(T_Prestamos[[#This Row],[Situación]]="Activos",IF(T_Prestamos[[#This Row],[Tipo préstamo]]="Francés",DATEDIF(T_Prestamos[[#This Row],[firma préstamo]],DATE(YEAR(TODAY()),1,1),"m"),0),0) -> 0 | Z29: =IF(T_Prestamos[[#This Row],[Situación]]="Activos",IF(T_Prestamos[[#This Row],[Tipo préstamo]]="Americano",T_Prestamos[[#This Row],[Importe]]*T_Prestamos[[#This Row],[% interés ordinario]],-CUMIPMT(T_Prestamos[[#This Row],[% interés ordinario]]/12,T_Prestamos[[#This Row],[Años]]*12,T_Prestamos[[#This Row],[Importe]],T_Prestamos[[#This Row],[Primera cuota año]],T_Prestamos[[#This Row],[Primera cuota año]]+11,0)),0) -> 0 | AA29: =IF(T_Prestamos[[#This Row],[firma préstamo]]>DATE(YEAR(TODAY())-1,MONTH(TODAY()),DAY(TODAY())),T_Prestamos[[#This Row],[Importe]]*T_Prestamos[[#This Row],[% apertura]],0) -> 0
B30: 2026 | C30: Boró - Rivas_Vaciamadrid - Persona física | D30: 43524 | E30: 15 | F30: 18000 | G30: 0.125 | H30: 0.145 | I30: =167565/40500*18000 -> 74473.333 | J30: =IF(T_Prestamos[[#This Row],[Garantía]]="","",T_Prestamos[[#This Row],[Pendiente]]/T_Prestamos[[#This Row],[Garantía]]) -> 0.18022908 | K30: Física | L30: Francés | M30: Silex | N30: Activos | Q30: =IF(T_Prestamos[[#This Row],[Situación]]="Cancelados",T_Prestamos[[#This Row],[Fecha cancelación]],TODAY())-T_Prestamos[[#This Row],[firma préstamo]] -> 2572 | R30: =IF(T_Prestamos[[#This Row],[Situación]]="Cancelada","",DATEDIF(T_Prestamos[[#This Row],[firma préstamo]],TODAY(),"m")) -> 84 | S30: =IF(T_Prestamos[[#This Row],[Situación]]="Cancelados",0,IF(T_Prestamos[[#This Row],[Tipo préstamo]]="Americano",T_Prestamos[[#This Row],[Importe]],T_Prestamos[[#This Row],[Importe]]+CUMPRINC(G30/12,E30*12,F30,1,R30,0))) -> 13422.26 | T30: =IF(T_Prestamos[[#This Row],[Situación]]="Cancelados",0,IF(T_Prestamos[[#This Row],[Tipo préstamo]]="Americano",T_Prestamos[[#This Row],[Pendiente]]*T_Prestamos[[#This Row],[% interés ordinario]],-CUMIPMT(G30/12,E30*12,F30,R30,R30+11,0))) -> 1630.1271 | U30: 0 | V30: =T_Prestamos[[#This Row],[% apertura]]*T_Prestamos[[#This Row],[Importe]] -> 0 | X30: Tomasa Palacios Torres | Y30: =IF(T_Prestamos[[#This Row],[Situación]]="Activos",IF(T_Prestamos[[#This Row],[Tipo préstamo]]="Francés",DATEDIF(T_Prestamos[[#This Row],[firma préstamo]],DATE(YEAR(TODAY()),1,1),"m"),0),0) -> 82 | Z30: =IF(T_Prestamos[[#This Row],[Situación]]="Activos",IF(T_Prestamos[[#This Row],[Tipo préstamo]]="Americano",T_Prestamos[[#This Row],[Importe]]*T_Prestamos[[#This Row],[% interés ordinario]],-CUMIPMT(T_Prestamos[[#This Row],[% interés ordinario]]/12,T_Prestamos[[#This Row],[Años]]*12,T_Prestamos[[#This Row],[Importe]],T_Prestamos[[#This Row],[Primera cuota año]],T_Prestamos[[#This Row],[Primera cuota año]]+11,0)),0) -> 1651.2982 | AA30: =IF(T_Prestamos[[#This Row],[firma préstamo]]>DATE(YEAR(TODAY())-1,MONTH(TODAY()),DAY(TODAY())),T_Prestamos[[#This Row],[Importe]]*T_Prestamos[[#This Row],[% apertura]],0) -> 0
